
<class 'torch.Tensor'>
Traceback (most recent call last):
  File "/home/kapi/Programming/Internship/cnn-mnist/resnet_finetuned.py", line 95, in <module>
    model = train_model(model, loss_fn, optimizer, num_epochs)
            ^^^^^^^^^^^^^^^^^^^^^^^^^^^^^^^^^^^^^^^^^^^^^^^^^^
  File "/home/kapi/Programming/Internship/cnn-mnist/resnet_finetuned.py", line 82, in train_model
    for i, (images, labels) in enumerate(train):
  File "/usr/lib/python3.11/site-packages/torch/utils/data/dataloader.py", line 630, in __next__
    data = self._next_data()
           ^^^^^^^^^^^^^^^^^
  File "/usr/lib/python3.11/site-packages/torch/utils/data/dataloader.py", line 1345, in _next_data
    return self._process_data(data)
           ^^^^^^^^^^^^^^^^^^^^^^^^
  File "/usr/lib/python3.11/site-packages/torch/utils/data/dataloader.py", line 1371, in _process_data
    data.reraise()
  File "/usr/lib/python3.11/site-packages/torch/_utils.py", line 694, in reraise
    raise exception
ValueError: Caught ValueError in DataLoader worker process 0.
Original Traceback (most recent call last):
  File "/usr/lib/python3.11/site-packages/torch/utils/data/_utils/worker.py", line 308, in _worker_loop
    data = fetcher.fetch(index)
           ^^^^^^^^^^^^^^^^^^^^
  File "/usr/lib/python3.11/site-packages/torch/utils/data/_utils/fetch.py", line 49, in fetch
    data = self.dataset.__getitems__(possibly_batched_index)
           ^^^^^^^^^^^^^^^^^^^^^^^^^^^^^^^^^^^^^^^^^^^^^^^^^
  File "/usr/lib/python3.11/site-packages/torch/utils/data/dataset.py", line 364, in __getitems__
    return [self.dataset[self.indices[idx]] for idx in indices]
           ^^^^^^^^^^^^^^^^^^^^^^^^^^^^^^^^^^^^^^^^^^^^^^^^^^^^
  File "/usr/lib/python3.11/site-packages/torch/utils/data/dataset.py", line 364, in <listcomp>
    return [self.dataset[self.indices[idx]] for idx in indices]
            ~~~~~~~~~~~~^^^^^^^^^^^^^^^^^^^
  File "/usr/lib/python3.11/site-packages/torchvision/datasets/mnist.py", line 142, in __getitem__
    img = Image.fromarray(img.numpy(), mode="L")
          ^^^^^^^^^^^^^^^^^^^^^^^^^^^^^^^^^^^^^^
  File "/usr/lib/python3.11/site-packages/PIL/Image.py", line 3113, in fromarray
    raise ValueError(msg)
ValueError: Too many dimensions: 3 > 2.